Workbook
Name Species: 'Analysis RAW'!$A:$A
Name Total_Catch_tonnes: 'Analysis RAW'!$B:$B

Sheet ABOUT
A1: 📊 INDONESIA FISHERIES ANALYSIS (2018-2022)
A3: Author | B3: : Radinal
A4: Role | B4: : Aspiring Data Analyst
A5: Email | B5: : radiradinal@outlook.com
A6: LinkedIn | B6: : https://www.linkedin.com/in/radinal-radinal-319b8972/
A7: Last Update | B7: : May 25th 2026

Sheet ORIGINAL DATA
A1: Country (Name) | B1: ASFIS species (Name) | C1: FAO major fishing area (Name) | D1: Unit (Name) | E1: Unit | F1: [2018] | G1: S | H1: [2019] | I1: S | J1: [2020] | K1: S | L1: [2021] | M1: S | N1: [2022] | O1: S
A2: Indonesia | B2: [Barbonymus balleroides] | C2: Asia - Inland waters | D2: Tonnes - live weight | E2: TLW, Number | F2: 310.97 | H2: 624.25 | J2: 1152.59 | L2: 1163.62 | N2: 1104.2
A3: Indonesia | B3: [Thynnichthys vaillanti] | C3: Asia - Inland waters | D3: Tonnes - live weight | E3: TLW, Number | F3: 375.07 | H3: 1821.24 | J3: 3547.79 | L3: 3169.49 | N3: 4617.35
A4: Indonesia | B4: [Puntioplites waandersi] | C4: Asia - Inland waters | D4: Tonnes - live weight | E4: TLW, Number | F4: 25.12 | H4: 917.88 | J4: 937.6 | L4: 486.85 | N4: 327.2
A5: Indonesia | B5: [Mystus spp] | C5: Asia - Inland waters | D5: Tonnes - live weight | E5: TLW, Number | F5: 0 | G5: ... | H5: 14705.2 | J5: 11865.38 | L5: 10433.33 | N5: 12595.14
A6: Indonesia | B6: [Cyclocheilichthys armatus] | C6: Asia - Inland waters | D6: Tonnes - live weight | E6: TLW, Number | F6: 4.89 | H6: 0 | I6: ... | J6: 0 | K6: ... | L6: 0 | M6: ... | N6: 0 | O6: ...
A7: Indonesia | B7: [Pangasius djambal] | C7: Asia - Inland waters | D7: Tonnes - live weight | E7: TLW, Number | F7: 26736.88 | H7: 7849.75 | J7: 4490.87 | L7: 7999.47 | N7: 9113.14
A8: Indonesia | B8: [Mystus nigriceps] | C8: Asia - Inland waters | D8: Tonnes - live weight | E8: TLW, Number | F8: 5005.33 | H8: 8352.36 | J8: 8579.96 | L8: 5271.77 | N8: 5384.96
A9: Indonesia | B9: [Mystacoleucus padangensis] | C9: Asia - Inland waters | D9: Tonnes - live weight | E9: TLW, Number | F9: 839.07 | H9: 367.16 | J9: 848.89 | L9: 1114.73 | N9: 1636.89
A10: Indonesia | B10: [Gymnothorax spp] | C10: Indian Ocean, Eastern | D10: Tonnes - live weight | E10: TLW, Number | F10: 0 | G10: ... | H10: 75.09 | J10: 43.69 | L10: 68.91 | N10: 91.13
A11: Indonesia | B11: [Lethrinus spp] | C11: Indian Ocean, Eastern | D11: Tonnes - live weight | E11: TLW, Number | F11: 0 | G11: ... | H11: 8282.94 | J11: 4309.66 | L11: 1367.73 | N11: 1782.86
A12: Indonesia | B12: [Muraenesocidae] | C12: Indian Ocean, Eastern | D12: Tonnes - live weight | E12: TLW, Number | F12: 0 | G12: ... | H12: 267.13 | J12: 796.34 | L12: 765 | N12: 916.98
A13: Indonesia | B13: [Gymnothorax spp] | C13: Pacific, Western Central | D13: Tonnes - live weight | E13: TLW, Number | F13: 0 | G13: ... | H13: 172.78 | J13: 135.99 | L13: 134.34 | N13: 143.3
A14: Indonesia | B14: [Lethrinus spp] | C14: Pacific, Western Central | D14: Tonnes - live weight | E14: TLW, Number | F14: 0 | G14: ... | H14: 41663.08 | J14: 41531.05 | L14: 55136.8 | N14: 45348.56
A15: Indonesia | B15: [Muraenesocidae] | C15: Pacific, Western Central | D15: Tonnes - live weight | E15: TLW, Number | F15: 0 | G15: ... | H15: 14444.01 | J15: 16016.36 | L15: 20437.02 | N15: 14565.8
A16: Indonesia | B16: Akiami paste shrimp | C16: Indian Ocean, Eastern | D16: Tonnes - live weight | E16: TLW, Number | F16: 0 | G16: ... | H16: 0 | I16: ... | J16: 0 | K16: ... | L16: 0 | M16: ... | N16: 0 | O16: ...
A17: Indonesia | B17: Albacore | C17: Indian Ocean, Eastern | D17: Tonnes - live weight | E17: TLW, Number | F17: 5604.51 | H17: 6477.73 | J17: 10568.59 | L17: 8896.48 | N17: 13153.82
A18: Indonesia | B18: Albacore | C18: Pacific, Western Central | D18: Tonnes - live weight | E18: TLW, Number | F18: 257 | H18: 21 | J18: 168 | L18: 87 | N18: 84
A19: Indonesia | B19: Anchovies, etc. nei | C19: Indian Ocean, Eastern | D19: Tonnes - live weight | E19: TLW, Number | F19: 0 | G19: ... | H19: 32492.23 | J19: 28168.29 | L19: 24466.91 | N19: 23501.35
A20: Indonesia | B20: Anchovies, etc. nei | C20: Pacific, Western Central | D20: Tonnes - live weight | E20: TLW, Number | F20: 0 | G20: ... | H20: 166228.18 | J20: 112498.79 | L20: 102356.52 | N20: 99724.33
A21: Indonesia | B21: Aquatic invertebrates nei | C21: Asia - Inland waters | D21: Tonnes - live weight | E21: TLW, Number | F21: 800 | G21: I | H21: 800 | I21: I | J21: 600 | K21: I | L21: 800 | M21: I | N21: 850 | O21: I
A22: Indonesia | B22: Aquatic invertebrates nei | C22: Indian Ocean, Eastern | D22: Tonnes - live weight | E22: TLW, Number | F22: 20000 | G22: I | H22: 18000 | I22: I | J22: 15000 | K22: I | L22: 10000 | M22: I | N22: 13000 | O22: I
A23: Indonesia | B23: Aquatic invertebrates nei | C23: Pacific, Western Central | D23: Tonnes - live weight | E23: TLW, Number | F23: 30000 | G23: I | H23: 25000 | I23: I | J23: 20000 | K23: I | L23: 19000 | M23: I | N23: 22000 | O23: I
A24: Indonesia | B24: Asian bonytongue | C24: Asia - Inland waters | D24: Tonnes - live weight | E24: TLW, Number | F24: 0 | G24: ... | H24: 0 | I24: ... | J24: 0 | K24: ... | L24: 0 | M24: ... | N24: 0 | O24: ...
A25: Indonesia | B25: Asian redtail catfish | C25: Asia - Inland waters | D25: Tonnes - live weight | E25: TLW, Number | F25: 37723.7 | H25: 31724.92 | J25: 18376.43 | L25: 22503.04 | N25: 18030.09
A26: Indonesia | B26: Asian swamp eel | C26: Asia - Inland waters | D26: Tonnes - live weight | E26: TLW, Number | F26: 0 | G26: ... | H26: 3573.39 | J26: 3658.11 | L26: 3584.18 | N26: 3924.95
A27: Indonesia | B27: Bald glassy | C27: Indian Ocean, Eastern | D27: Tonnes - live weight | E27: TLW, Number | F27: 0 | G27: ... | H27: 226.38 | J27: 588.02 | L27: 670.67 | N27: 684.77
A28: Indonesia | B28: Bali sardinella | C28: Indian Ocean, Eastern | D28: Tonnes - live weight | E28: TLW, Number | F28: 15038.6 | H28: 79733.17 | J28: 33516.36 | L28: 47220.33 | N28: 32499.56
A29: Indonesia | B29: Bali sardinella | C29: Pacific, Western Central | D29: Tonnes - live weight | E29: TLW, Number | F29: 35960.6 | H29: 10284.6 | J29: 1273.08 | L29: 8455.09 | N29: 20511.3
A30: Indonesia | B30: Banana prawn | C30: Indian Ocean, Eastern | D30: Tonnes - live weight | E30: TLW, Number | F30: 17265.78 | H30: 10298.39 | J30: 6939.36 | L30: 10610.5 | N30: 8799.22
A31: Indonesia | B31: Banana prawn | C31: Pacific, Western Central | D31: Tonnes - live weight | E31: TLW, Number | F31: 46809.35 | H31: 22897.06 | J31: 15326.01 | L31: 17345.02 | N31: 26539.2
A32: Indonesia | B32: Banded archerfish | C32: Asia - Inland waters | D32: Tonnes - live weight | E32: TLW, Number | F32: 0 | G32: ... | H32: 33.42 | J32: 3.55 | L32: 0.6 | N32: 0.02
A33: Indonesia | B33: Barracudas nei | C33: Indian Ocean, Eastern | D33: Tonnes - live weight | E33: TLW, Number | F33: 0 | G33: ... | H33: 10216.31 | J33: 12964.78 | L33: 14752.3 | N33: 14000.23
A34: Indonesia | B34: Barracudas nei | C34: Pacific, Western Central | D34: Tonnes - live weight | E34: TLW, Number | F34: 0 | G34: ... | H34: 22127.95 | J34: 24667.66 | L34: 23042.31 | N34: 22525.87
A35: Indonesia | B35: Barracudinas, etc. nei | C35: Indian Ocean, Eastern | D35: Tonnes - live weight | E35: TLW, Number | F35: 0 | G35: ... | H35: 1888.46 | J35: 1963.79 | L35: 13171.64 | N35: 2770.63
A36: Indonesia | B36: Barracudinas, etc. nei | C36: Pacific, Western Central | D36: Tonnes - live weight | E36: TLW, Number | F36: 0 | G36: ... | H36: 5872.69 | J36: 8580.51 | L36: 6111.72 | N36: 4357.41
A37: Indonesia | B37: Barramundi(=Giant seaperch) | C37: Asia - Inland waters | D37: Tonnes - live weight | E37: TLW, Number | F37: 0 | G37: ... | H37: 466.77 | J37: 478.49 | L37: 616.88 | N37: 323.34
A38: Indonesia | B38: Barramundi(=Giant seaperch) | C38: Indian Ocean, Eastern | D38: Tonnes - live weight | E38: TLW, Number | F38: 6000 | G38: I | H38: 5133.86 | J38: 4772.64 | L38: 4225.49 | N38: 5612.35
A39: Indonesia | B39: Barramundi(=Giant seaperch) | C39: Pacific, Western Central | D39: Tonnes - live weight | E39: TLW, Number | F39: 40000 | G39: I | H39: 31264.88 | J39: 29439.8 | L39: 32160.88 | N39: 33351.26
A40: Indonesia | B40: Beardless barb | C40: Asia - Inland waters | D40: Tonnes - live weight | E40: TLW, Number | F40: 648.89 | H40: 226.38 | J40: 438.77 | L40: 484.03 | N40: 1034.77
...

Sheet Price (WEB SCRAPPING)
A1: Species name | B1: Range Price per kg | C1: min_price_kg | D1: max_price_kg
A2: Scads nei | B2: $0.95 – $1.60 | C2: =MID(B2,2,FIND("–",B2)-3) -> 0.95 | D2: =MID(B2,FIND("–",B2)+3,LEN(B2)-FIND("–",B2)-1) -> 1.60
A3: Marine fishes nei | B3: $0.50 – $1.10 | C3: =MID(B3,2,FIND("–",B3)-3) -> 0.50 | D3: =MID(B3,FIND("–",B3)+3,LEN(B3)-FIND("–",B3)-1) -> 1.10
A4: Skipjack tuna | B4: $1.45 – $1.85 | C4: =MID(B4,2,FIND("–",B4)-3) -> 1.45 | D4: =MID(B4,FIND("–",B4)+3,LEN(B4)-FIND("–",B4)-1) -> 1.85
A5: Yellowfin tuna | B5: $2.10 – $14.50 | C5: =MID(B5,2,FIND("–",B5)-3) -> 2.10 | D5: =MID(B5,FIND("–",B5)+3,LEN(B5)-FIND("–",B5)-1) -> 14.50
A6: Indian mackerels nei | B6: $0.90 – $1.40 | C6: =MID(B6,2,FIND("–",B6)-3) -> 0.90 | D6: =MID(B6,FIND("–",B6)+3,LEN(B6)-FIND("–",B6)-1) -> 1.40
A7: Common squids nei | B7: $3.20 – $5.80 | C7: =MID(B7,2,FIND("–",B7)-3) -> 3.20 | D7: =MID(B7,FIND("–",B7)+3,LEN(B7)-FIND("–",B7)-1) -> 5.80
A8: Narrow-barred Spanish mackerel | B8: $3.50 – $5.00 | C8: =MID(B8,2,FIND("–",B8)-3) -> 3.50 | D8: =MID(B8,FIND("–",B8)+3,LEN(B8)-FIND("–",B8)-1) -> 5.00
A9: Snappers nei | B9: $5.50 – $9.00 | C9: =MID(B9,2,FIND("–",B9)-3) -> 5.50 | D9: =MID(B9,FIND("–",B9)+3,LEN(B9)-FIND("–",B9)-1) -> 9.00
A10: Longtail tuna | B10: $1.80 – $2.60 | C10: =MID(B10,2,FIND("–",B10)-3) -> 1.80 | D10: =MID(B10,FIND("–",B10)+3,LEN(B10)-FIND("–",B10)-1) -> 2.60
A11: Frigate tuna | B11: $1.10 – $1.60 | C11: =MID(B11,2,FIND("–",B11)-3) -> 1.10 | D11: =MID(B11,FIND("–",B11)+3,LEN(B11)-FIND("–",B11)-1) -> 1.60
A12: Carangids nei | B12: $1.00 – $1.80 | C12: =MID(B12,2,FIND("–",B12)-3) -> 1.00 | D12: =MID(B12,FIND("–",B12)+3,LEN(B12)-FIND("–",B12)-1) -> 1.80
A13: Groupers, seabasses nei | B13: $6.00 – $11.50 | C13: =MID(B13,2,FIND("–",B13)-3) -> 6.00 | D13: =MID(B13,FIND("–",B13)+3,LEN(B13)-FIND("–",B13)-1) -> 11.50
... A21: Sea catfishes nei | B21: $0.60 – $1.25 | C21: =MID(B21,2,FIND("–",B21)-3) -> 0.60 | D21: =MID(B21,FIND("–",B21)+3,LEN(B21)-FIND("–",B21)-1) -> 1.25

Sheet Data
A1: Country (Name) | B1: ASFIS species (Name) | C1: FAO major fishing area (Name) | D1: Unit (Name) | E1: Unit | F1: [2018] | G1: S | H1: [2019] | I1: S2 | J1: [2020] | K1: S3 | L1: [2021] | M1: S4 | N1: [2022] | O1: S5 | P1: Total
A2: Indonesia | B2: Barbonymus balleroides | C2: Asia - Inland waters | D2: Tonnes - live weight | E2: TLW, Number | F2: 310.97 | H2: 624.25 | J2: 1152.59 | L2: 1163.62 | N2: 1104.2 | P2: =SUM(F2,H2,J2,L2,N2) -> 4355.63
A3: Indonesia | B3: Thynnichthys vaillanti | C3: Asia - Inland waters | D3: Tonnes - live weight | E3: TLW, Number | F3: 375.07 | H3: 1821.24 | J3: 3547.79 | L3: 3169.49 | N3: 4617.35 | P3: =SUM(F3,H3,J3,L3,N3) -> 13530.94
A4: Indonesia | B4: Puntioplites waandersi | C4: Asia - Inland waters | D4: Tonnes - live weight | E4: TLW, Number | F4: 25.12 | H4: 917.88 | J4: 937.6 | L4: 486.85 | N4: 327.2 | P4: =SUM(F4,H4,J4,L4,N4) -> 2694.65
A5: Indonesia | B5: Mystus spp | C5: Asia - Inland waters | D5: Tonnes - live weight | E5: TLW, Number | F5: 0 | G5: ... | H5: 14705.2 | J5: 11865.38 | L5: 10433.33 | N5: 12595.14 | P5: =SUM(F5,H5,J5,L5,N5) -> 49599.05
A6: Indonesia | B6: Cyclocheilichthys armatus | C6: Asia - Inland waters | D6: Tonnes - live weight | E6: TLW, Number | F6: 4.89 | H6: 0 | I6: ... | J6: 0 | K6: ... | L6: 0 | M6: ... | N6: 0 | O6: ... | P6: =SUM(F6,H6,J6,L6,N6) -> 4.89
A7: Indonesia | B7: Pangasius djambal | C7: Asia - Inland waters | D7: Tonnes - live weight | E7: TLW, Number | F7: 26736.88 | H7: 7849.75 | J7: 4490.87 | L7: 7999.47 | N7: 9113.14 | P7: =SUM(F7,H7,J7,L7,N7) -> 56190.11
A8: Indonesia | B8: Mystus nigriceps | C8: Asia - Inland waters | D8: Tonnes - live weight | E8: TLW, Number | F8: 5005.33 | H8: 8352.36 | J8: 8579.96 | L8: 5271.77 | N8: 5384.96 | P8: =SUM(F8,H8,J8,L8,N8) -> 32594.38
A9: Indonesia | B9: Mystacoleucus padangensis | C9: Asia - Inland waters | D9: Tonnes - live weight | E9: TLW, Number | F9: 839.07 | H9: 367.16 | J9: 848.89 | L9: 1114.73 | N9: 1636.89 | P9: =SUM(F9,H9,J9,L9,N9) -> 4806.74
A10: Indonesia | B10: Gymnothorax spp | C10: Indian Ocean, Eastern | D10: Tonnes - live weight | E10: TLW, Number | F10: 0 | G10: ... | H10: 75.09 | J10: 43.69 | L10: 68.91 | N10: 91.13 | P10: =SUM(F10,H10,J10,L10,N10) -> 278.82
A11: Indonesia | B11: Lethrinus spp | C11: Indian Ocean, Eastern | D11: Tonnes - live weight | E11: TLW, Number | F11: 0 | G11: ... | H11: 8282.94 | J11: 4309.66 | L11: 1367.73 | N11: 1782.86 | P11: =SUM(F11,H11,J11,L11,N11) -> 15743.19
A12: Indonesia | B12: Muraenesocidae | C12: Indian Ocean, Eastern | D12: Tonnes - live weight | E12: TLW, Number | F12: 0 | G12: ... | H12: 267.13 | J12: 796.34 | L12: 765 | N12: 916.98 | P12: =SUM(F12,H12,J12,L12,N12) -> 2745.45
A13: Indonesia | B13: Gymnothorax spp | C13: Pacific, Western Central | D13: Tonnes - live weight | E13: TLW, Number | F13: 0 | G13: ... | H13: 172.78 | J13: 135.99 | L13: 134.34 | N13: 143.3 | P13: =SUM(F13,H13,J13,L13,N13) -> 586.41
A14: Indonesia | B14: Lethrinus spp | C14: Pacific, Western Central | D14: Tonnes - live weight | E14: TLW, Number | F14: 0 | G14: ... | H14: 41663.08 | J14: 41531.05 | L14: 55136.8 | N14: 45348.56 | P14: =SUM(F14,H14,J14,L14,N14) -> 183679.49
A15: Indonesia | B15: Muraenesocidae | C15: Pacific, Western Central | D15: Tonnes - live weight | E15: TLW, Number | F15: 0 | G15: ... | H15: 14444.01 | J15: 16016.36 | L15: 20437.02 | N15: 14565.8 | P15: =SUM(F15,H15,J15,L15,N15) -> 65463.19
A16: Indonesia | B16: Albacore | C16: Indian Ocean, Eastern | D16: Tonnes - live weight | E16: TLW, Number | F16: 5604.51 | H16: 6477.73 | J16: 10568.59 | L16: 8896.48 | N16: 13153.82 | P16: =SUM(F16,H16,J16,L16,N16) -> 44701.13
A17: Indonesia | B17: Albacore | C17: Pacific, Western Central | D17: Tonnes - live weight | E17: TLW, Number | F17: 257 | H17: 21 | J17: 168 | L17: 87 | N17: 84 | P17: =SUM(F17,H17,J17,L17,N17) -> 617
A18: Indonesia | B18: Anchovies, etc. nei | C18: Indian Ocean, Eastern | D18: Tonnes - live weight | E18: TLW, Number | F18: 0 | G18: ... | H18: 32492.23 | J18: 28168.29 | L18: 24466.91 | N18: 23501.35 | P18: =SUM(F18,H18,J18,L18,N18) -> 108628.78
A19: Indonesia | B19: Anchovies, etc. nei | C19: Pacific, Western Central | D19: Tonnes - live weight | E19: TLW, Number | F19: 0 | G19: ... | H19: 166228.18 | J19: 112498.79 | L19: 102356.52 | N19: 99724.33 | P19: =SUM(F19,H19,J19,L19,N19) -> 480807.82
A20: Indonesia | B20: Aquatic invertebrates nei | C20: Asia - Inland waters | D20: Tonnes - live weight | E20: TLW, Number | F20: 800 | G20: I | H20: 800 | I20: I | J20: 600 | K20: I | L20: 800 | M20: I | N20: 850 | O20: I | P20: =SUM(F20,H20,J20,L20,N20) -> 3850
A21: Indonesia | B21: Aquatic invertebrates nei | C21: Indian Ocean, Eastern | D21: Tonnes - live weight | E21: TLW, Number | F21: 20000 | G21: I | H21: 18000 | I21: I | J21: 15000 | K21: I | L21: 10000 | M21: I | N21: 13000 | O21: I | P21: =SUM(F21,H21,J21,L21,N21) -> 76000
A22: Indonesia | B22: Aquatic invertebrates nei | C22: Pacific, Western Central | D22: Tonnes - live weight | E22: TLW, Number | F22: 30000 | G22: I | H22: 25000 | I22: I | J22: 20000 | K22: I | L22: 19000 | M22: I | N22: 22000 | O22: I | P22: =SUM(F22,H22,J22,L22,N22) -> 116000
A23: Indonesia | B23: Asian redtail catfish | C23: Asia - Inland waters | D23: Tonnes - live weight | E23: TLW, Number | F23: 37723.7 | H23: 31724.92 | J23: 18376.43 | L23: 22503.04 | N23: 18030.09 | P23: =SUM(F23,H23,J23,L23,N23) -> 128358.18
A24: Indonesia | B24: Asian swamp eel | C24: Asia - Inland waters | D24: Tonnes - live weight | E24: TLW, Number | F24: 0 | G24: ... | H24: 3573.39 | J24: 3658.11 | L24: 3584.18 | N24: 3924.95 | P24: =SUM(F24,H24,J24,L24,N24) -> 14740.63
A25: Indonesia | B25: Bald glassy | C25: Indian Ocean, Eastern | D25: Tonnes - live weight | E25: TLW, Number | F25: 0 | G25: ... | H25: 226.38 | J25: 588.02 | L25: 670.67 | N25: 684.77 | P25: =SUM(F25,H25,J25,L25,N25) -> 2169.84
A26: Indonesia | B26: Bali sardinella | C26: Indian Ocean, Eastern | D26: Tonnes - live weight | E26: TLW, Number | F26: 15038.6 | H26: 79733.17 | J26: 33516.36 | L26: 47220.33 | N26: 32499.56 | P26: =SUM(F26,H26,J26,L26,N26) -> 208008.02
A27: Indonesia | B27: Bali sardinella | C27: Pacific, Western Central | D27: Tonnes - live weight | E27: TLW, Number | F27: 35960.6 | H27: 10284.6 | J27: 1273.08 | L27: 8455.09 | N27: 20511.3 | P27: =SUM(F27,H27,J27,L27,N27) -> 76484.67
A28: Indonesia | B28: Banana prawn | C28: Indian Ocean, Eastern | D28: Tonnes - live weight | E28: TLW, Number | F28: 17265.78 | H28: 10298.39 | J28: 6939.36 | L28: 10610.5 | N28: 8799.22 | P28: =SUM(F28,H28,J28,L28,N28) -> 53913.25
A29: Indonesia | B29: Banana prawn | C29: Pacific, Western Central | D29: Tonnes - live weight | E29: TLW, Number | F29: 46809.35 | H29: 22897.06 | J29: 15326.01 | L29: 17345.02 | N29: 26539.2 | P29: =SUM(F29,H29,J29,L29,N29) -> 128916.64
A30: Indonesia | B30: Banded archerfish | C30: Asia - Inland waters | D30: Tonnes - live weight | E30: TLW, Number | F30: 0 | G30: ... | H30: 33.42 | J30: 3.55 | L30: 0.6 | N30: 0.02 | P30: =SUM(F30,H30,J30,L30,N30) -> 37.59
A31: Indonesia | B31: Barracudas nei | C31: Indian Ocean, Eastern | D31: Tonnes - live weight | E31: TLW, Number | F31: 0 | G31: ... | H31: 10216.31 | J31: 12964.78 | L31: 14752.3 | N31: 14000.23 | P31: =SUM(F31,H31,J31,L31,N31) -> 51933.62
A32: Indonesia | B32: Barracudas nei | C32: Pacific, Western Central | D32: Tonnes - live weight | E32: TLW, Number | F32: 0 | G32: ... | H32: 22127.95 | J32: 24667.66 | L32: 23042.31 | N32: 22525.87 | P32: =SUM(F32,H32,J32,L32,N32) -> 92363.79
A33: Indonesia | B33: Barracudinas, etc. nei | C33: Indian Ocean, Eastern | D33: Tonnes - live weight | E33: TLW, Number | F33: 0 | G33: ... | H33: 1888.46 | J33: 1963.79 | L33: 13171.64 | N33: 2770.63 | P33: =SUM(F33,H33,J33,L33,N33) -> 19794.52
A34: Indonesia | B34: Barracudinas, etc. nei | C34: Pacific, Western Central | D34: Tonnes - live weight | E34: TLW, Number | F34: 0 | G34: ... | H34: 5872.69 | J34: 8580.51 | L34: 6111.72 | N34: 4357.41 | P34: =SUM(F34,H34,J34,L34,N34) -> 24922.33
A35: Indonesia | B35: Barramundi(=Giant seaperch) | C35: Asia - Inland waters | D35: Tonnes - live weight | E35: TLW, Number | F35: 0 | G35: ... | H35: 466.77 | J35: 478.49 | L35: 616.88 | N35: 323.34 | P35: =SUM(F35,H35,J35,L35,N35) -> 1885.48
A36: Indonesia | B36: Barramundi(=Giant seaperch) | C36: Indian Ocean, Eastern | D36: Tonnes - live weight | E36: TLW, Number | F36: 6000 | G36: I | H36: 5133.86 | J36: 4772.64 | L36: 4225.49 | N36: 5612.35 | P36: =SUM(F36,H36,J36,L36,N36) -> 25744.34
A37: Indonesia | B37: Barramundi(=Giant seaperch) | C37: Pacific, Western Central | D37: Tonnes - live weight | E37: TLW, Number | F37: 40000 | G37: I | H37: 31264.88 | J37: 29439.8 | L37: 32160.88 | N37: 33351.26 | P37: =SUM(F37,H37,J37,L37,N37) -> 166216.82
A38: Indonesia | B38: Beardless barb | C38: Asia - Inland waters | D38: Tonnes - live weight | E38: TLW, Number | F38: 648.89 | H38: 226.38 | J38: 438.77 | L38: 484.03 | N38: 1034.77 | P38: =SUM(F38,H38,J38,L38,N38) -> 2832.84
A39: Indonesia | B39: Bichique | C39: Pacific, Western Central | D39: Tonnes - live weight | E39: TLW, Number | F39: 0 | G39: ... | H39: 2123.72 | J39: 4508.72 | L39: 3465.43 | N39: 4788.03 | P39: =SUM(F39,H39,J39,L39,N39) -> 14885.9
A40: Indonesia | B40: Bigeye scad | C40: Indian Ocean, Eastern | D40: Tonnes - live weight | E40: TLW, Number | F40: 5576.66 | H40: 13767.12 | J40: 11005.64 | L40: 9626.74 | N40: 8990.75 | P40: =SUM(F40,H40,J40,L40,N40) -> 48966.91
...

Sheet Analysis RAW
A1: Species | B1: Total_Catch_tonnes
A2: {=_xlfn.UNIQUE(Data!B2:B413)} -> Barbonymus balleroides | B2: =SUMIF(Data!B2:B413,'Analysis RAW'!A2,Data!P2:P415) -> 4355.63
A3: Thynnichthys vaillanti | B3: =SUMIF(Data!B3:B414,'Analysis RAW'!A3,Data!P3:P416) -> 13530.94
A4: Puntioplites waandersi | B4: =SUMIF(Data!B4:B415,'Analysis RAW'!A4,Data!P4:P417) -> 2694.65
A5: Mystus spp | B5: =SUMIF(Data!B5:B416,'Analysis RAW'!A5,Data!P5:P418) -> 49599.05
A6: Cyclocheilichthys armatus | B6: =SUMIF(Data!B6:B417,'Analysis RAW'!A6,Data!P6:P419) -> 4.89
A7: Pangasius djambal | B7: =SUMIF(Data!B7:B418,'Analysis RAW'!A7,Data!P7:P420) -> 56190.11
A8: Mystus nigriceps | B8: =SUMIF(Data!B8:B419,'Analysis RAW'!A8,Data!P8:P421) -> 32594.38
A9: Mystacoleucus padangensis | B9: =SUMIF(Data!B9:B420,'Analysis RAW'!A9,Data!P9:P422) -> 4806.74
A10: Gymnothorax spp | B10: =SUMIF(Data!B10:B421,'Analysis RAW'!A10,Data!P10:P423) -> 865.23
A11: Lethrinus spp | B11: =SUMIF(Data!B11:B422,'Analysis RAW'!A11,Data!P11:P424) -> 199422.68
A12: Muraenesocidae | B12: =SUMIF(Data!B12:B423,'Analysis RAW'!A12,Data!P12:P425) -> 68208.64
A13: Albacore | B13: =SUMIF(Data!B13:B424,'Analysis RAW'!A13,Data!P13:P426) -> 45318.13
A14: Anchovies, etc. nei | B14: =SUMIF(Data!B14:B425,'Analysis RAW'!A14,Data!P14:P427) -> 589436.6
... A241: Zanzibar weed | B241: =SUMIF(Data!B241:B652,'Analysis RAW'!A241,Data!P241:P654) -> 976.47

Sheet Analysis
A1: Species | B1: Total_Catch_tonnes | C1: min_price_tonne | D1: max_price_tonne | E1: avg_price_tonne | F1: revenue_min_million | G1: revenue_max_million | I1: Top20 | J1: 2018 | K1: 2019 | L1: 2020 | M1: 2021 | N1: 2022 | O1: % Change 2018-2022
A2: Scads nei | B2: 2596480.6 | C2: =_xlfn.NUMBERVALUE(_xlfn.XLOOKUP(A2,Table8[Species name],Table8[min_price_kg],,0),".") -> 0.95 | D2: =_xlfn.NUMBERVALUE(_xlfn.XLOOKUP(A2,Table8[Species name],Table8[max_price_kg],,0),".") -> 1.6 | E2: =_xlfn.NUMBERVALUE(AVERAGE(C2:D2),".") -> 1275 | F2: =(B2*C2)/1000000 -> 2.4666565 | G2: =(B2*D2)/1000000 -> 4.1543689 | I2: Yellowfin tuna | J2: =SUMIFS(Data!F:F,Data!B:B,Analysis!$I5) -> 165717.52 | K2: =SUMIFS(Data!H:H,Data!B:B,Analysis!$I5) -> 116016.82 | L2: =SUMIFS(Data!J:J,Data!B:B,Analysis!$I5) -> 98505.77 | M2: =SUMIFS(Data!L:L,Data!B:B,Analysis!$I5) -> 99510.15 | N2: =SUMIFS(Data!N:N,Data!B:B,Analysis!$I5) -> 97096.67 | O2: =IFERROR((N2 - J2)/J2, (N2 - K2)/K2) -> -0.41408325
A3: Marine fishes nei | B3: 1993648.2 | C3: =_xlfn.NUMBERVALUE(_xlfn.XLOOKUP(A3,Table8[Species name],Table8[min_price_kg],,0),".") -> 0.5 | D3: =_xlfn.NUMBERVALUE(_xlfn.XLOOKUP(A3,Table8[Species name],Table8[max_price_kg],,0),".") -> 1.1 | E3: =_xlfn.NUMBERVALUE(AVERAGE(C3:D3),".") -> 8 | F3: =(B3*C3)/1000000 -> 0.99682408 | G3: =(B3*D3)/1000000 -> 2.193013 | I3: Frigate tuna | J3: =SUMIFS(Data!F:F,Data!B:B,Analysis!$I11) -> 339152.44 | K3: =SUMIFS(Data!H:H,Data!B:B,Analysis!$I11) -> 120830 | L3: =SUMIFS(Data!J:J,Data!B:B,Analysis!$I11) -> 131785.18 | M3: =SUMIFS(Data!L:L,Data!B:B,Analysis!$I11) -> 147263.05 | N3: =SUMIFS(Data!N:N,Data!B:B,Analysis!$I11) -> 175351.68 | O3: =IFERROR((N3 - J3)/J3, (N3 - K3)/K3) -> -0.4829709
A4: Skipjack tuna | B4: 1982631.8 | C4: =_xlfn.NUMBERVALUE(_xlfn.XLOOKUP(A4,Table8[Species name],Table8[min_price_kg],,0),".") -> 1.45 | D4: =_xlfn.NUMBERVALUE(_xlfn.XLOOKUP(A4,Table8[Species name],Table8[max_price_kg],,0),".") -> 1.85 | E4: =_xlfn.NUMBERVALUE(AVERAGE(C4:D4),".") -> 165 | F4: =(B4*C4)/1000000 -> 2.8748161 | G4: =(B4*D4)/1000000 -> 3.6678688 | I4: Sea catfishes nei | J4: =SUMIFS(Data!F:F,Data!B:B,Analysis!$I21) -> 0 | K4: =SUMIFS(Data!H:H,Data!B:B,Analysis!$I21) -> 195741.47 | L4: =SUMIFS(Data!J:J,Data!B:B,Analysis!$I21) -> 193755.33 | M4: =SUMIFS(Data!L:L,Data!B:B,Analysis!$I21) -> 199625.99 | N4: =SUMIFS(Data!N:N,Data!B:B,Analysis!$I21) -> 191853.06 | O4: =IFERROR((N4 - J4)/J4, (N4 - K4)/K4) -> -0.019865029
A5: Yellowfin tuna | B5: 1318443.3 | C5: =_xlfn.NUMBERVALUE(_xlfn.XLOOKUP(A5,Table8[Species name],Table8[min_price_kg],,0),".") -> 2.1 | D5: =_xlfn.NUMBERVALUE(_xlfn.XLOOKUP(A5,Table8[Species name],Table8[max_price_kg],,0),".") -> 14.5 | E5: =_xlfn.NUMBERVALUE(AVERAGE(C5:D5),".") -> 83 | F5: =(B5*C5)/1000000 -> 2.7687309 | G5: =(B5*D5)/1000000 -> 19.117427 | I5: Blue swimming crab | J5: =SUMIFS(Data!F:F,Data!B:B,Analysis!$I19) -> 80396.06 | K5: =SUMIFS(Data!H:H,Data!B:B,Analysis!$I19) -> 138557.05 | L5: =SUMIFS(Data!J:J,Data!B:B,Analysis!$I19) -> 120437.78 | M5: =SUMIFS(Data!L:L,Data!B:B,Analysis!$I19) -> 135456.45 | N5: =SUMIFS(Data!N:N,Data!B:B,Analysis!$I19) -> 138698.9 | O5: =IFERROR((N5 - J5)/J5, (N5 - K5)/K5) -> 0.72519524
A6: Indian mackerels nei | B6: 1099882.2 | C6: =_xlfn.NUMBERVALUE(_xlfn.XLOOKUP(A6,Table8[Species name],Table8[min_price_kg],,0),".") -> 0.9 | D6: =_xlfn.NUMBERVALUE(_xlfn.XLOOKUP(A6,Table8[Species name],Table8[max_price_kg],,0),".") -> 1.4 | E6: =_xlfn.NUMBERVALUE(AVERAGE(C6:D6),".") -> 115 | F6: =(B6*C6)/1000000 -> 0.98989396 | G6: =(B6*D6)/1000000 -> 1.5398351 | I6: Anchovies, etc. nei | J6: =SUMIFS(Data!F:F,Data!B:B,Analysis!$I18) -> 218295.12 | K6: =SUMIFS(Data!H:H,Data!B:B,Analysis!$I18) -> 194299.04 | L6: =SUMIFS(Data!J:J,Data!B:B,Analysis!$I18) -> 193583.84 | M6: =SUMIFS(Data!L:L,Data!B:B,Analysis!$I18) -> 204337.72 | N6: =SUMIFS(Data!N:N,Data!B:B,Analysis!$I18) -> 188724.51 | O6: =IFERROR((N6 - J6)/J6, (N6 - K6)/K6) -> -0.13546162
A7: Common squids nei | B7: 999240.23 | C7: =_xlfn.NUMBERVALUE(_xlfn.XLOOKUP(A7,Table8[Species name],Table8[min_price_kg],,0),".") -> 3.2 | D7: =_xlfn.NUMBERVALUE(_xlfn.XLOOKUP(A7,Table8[Species name],Table8[max_price_kg],,0),".") -> 5.8 | E7: =_xlfn.NUMBERVALUE(AVERAGE(C7:D7),".") -> 45 | F7: =(B7*C7)/1000000 -> 3.1975687 | G7: =(B7*D7)/1000000 -> 5.7955933 | I7: Longtail tuna | J7: =SUMIFS(Data!F:F,Data!B:B,Analysis!$I10) -> 370367.38 | K7: =SUMIFS(Data!H:H,Data!B:B,Analysis!$I10) -> 426847.34 | L7: =SUMIFS(Data!J:J,Data!B:B,Analysis!$I10) -> 374288.43 | M7: =SUMIFS(Data!L:L,Data!B:B,Analysis!$I10) -> 404358.08 | N7: =SUMIFS(Data!N:N,Data!B:B,Analysis!$I10) -> 406770.56 | O7: =IFERROR((N7 - J7)/J7, (N7 - K7)/K7) -> 0.09828938
A8: Narrow-barred Spanish mackerel | B8: 955753.78 | C8: =_xlfn.NUMBERVALUE(_xlfn.XLOOKUP(A8,Table8[Species name],Table8[min_price_kg],,0),".") -> 3.5 | D8: =_xlfn.NUMBERVALUE(_xlfn.XLOOKUP(A8,Table8[Species name],Table8[max_price_kg],,0),".") -> 5 | E8: =_xlfn.NUMBERVALUE(AVERAGE(C8:D8),".") -> 425 | F8: =(B8*C8)/1000000 -> 3.3451382 | G8: =(B8*D8)/1000000 -> 4.7787689 | I8: Goatfishes | J8: =SUMIFS(Data!F:F,Data!B:B,Analysis!$I17) -> 150950.74 | K8: =SUMIFS(Data!H:H,Data!B:B,Analysis!$I17) -> 172320.4 | L8: =SUMIFS(Data!J:J,Data!B:B,Analysis!$I17) -> 191016.24 | M8: =SUMIFS(Data!L:L,Data!B:B,Analysis!$I17) -> 193441.97 | N8: =SUMIFS(Data!N:N,Data!B:B,Analysis!$I17) -> 248024.43 | O8: =IFERROR((N8 - J8)/J8, (N8 - K8)/K8) -> 0.64308191
A9: Snappers nei | B9: 914382.35 | C9: =_xlfn.NUMBERVALUE(_xlfn.XLOOKUP(A9,Table8[Species name],Table8[min_price_kg],,0),".") -> 5.5 | D9: =_xlfn.NUMBERVALUE(_xlfn.XLOOKUP(A9,Table8[Species name],Table8[max_price_kg],,0),".") -> 9 | E9: =_xlfn.NUMBERVALUE(AVERAGE(C9:D9),".") -> 725 | F9: =(B9*C9)/1000000 -> 5.0291029 | G9: =(B9*D9)/1000000 -> 8.2294411 | I9: Snappers, jobfishes nei | J9: =SUMIFS(Data!F:F,Data!B:B,Analysis!$I20) -> 132296.25 | K9: =SUMIFS(Data!H:H,Data!B:B,Analysis!$I20) -> 142386.73 | L9: =SUMIFS(Data!J:J,Data!B:B,Analysis!$I20) -> 152072.16 | M9: =SUMIFS(Data!L:L,Data!B:B,Analysis!$I20) -> 167355.83 | N9: =SUMIFS(Data!N:N,Data!B:B,Analysis!$I20) -> 174157.4 | O9: =IFERROR((N9 - J9)/J9, (N9 - K9)/K9) -> 0.31641978
A10: Longtail tuna | B10: 882434.56 | C10: =_xlfn.NUMBERVALUE(_xlfn.XLOOKUP(A10,Table8[Species name],Table8[min_price_kg],,0),".") -> 1.8 | D10: =_xlfn.NUMBERVALUE(_xlfn.XLOOKUP(A10,Table8[Species name],Table8[max_price_kg],,0),".") -> 2.6 | E10: =_xlfn.NUMBERVALUE(AVERAGE(C10:D10),".") -> 22 | F10: =(B10*C10)/1000000 -> 1.5883822 | G10: =(B10*D10)/1000000 -> 2.2943299 | I10: Skipjack tuna | J10: =SUMIFS(Data!F:F,Data!B:B,Analysis!$I4) -> 114776.86 | K10: =SUMIFS(Data!H:H,Data!B:B,Analysis!$I4) -> 100217.62 | L10: =SUMIFS(Data!J:J,Data!B:B,Analysis!$I4) -> 90470.15 | M10: =SUMIFS(Data!L:L,Data!B:B,Analysis!$I4) -> 99882.83 | N10: =SUMIFS(Data!N:N,Data!B:B,Analysis!$I4) -> 110667.82 | O10: =IFERROR((N10 - J10)/J10, (N10 - K10)/K10) -> -0.035800248
A11: Frigate tuna | B11: 871949.25 | C11: =_xlfn.NUMBERVALUE(_xlfn.XLOOKUP(A11,Table8[Species name],Table8[min_price_kg],,0),".") -> 1.1 | D11: =_xlfn.NUMBERVALUE(_xlfn.XLOOKUP(A11,Table8[Species name],Table8[max_price_kg],,0),".") -> 1.6 | E11: =_xlfn.NUMBERVALUE(AVERAGE(C11:D11),".") -> 135 | F11: =(B11*C11)/1000000 -> 0.95914418 | G11: =(B11*D11)/1000000 -> 1.3951188 | I11: Snappers nei | J11: =SUMIFS(Data!F:F,Data!B:B,Analysis!$I9) -> 0 | K11: =SUMIFS(Data!H:H,Data!B:B,Analysis!$I9) -> 132550.85 | L11: =SUMIFS(Data!J:J,Data!B:B,Analysis!$I9) -> 155115.06 | M11: =SUMIFS(Data!L:L,Data!B:B,Analysis!$I9) -> 148926.72 | N11: =SUMIFS(Data!N:N,Data!B:B,Analysis!$I9) -> 131759.32 | O11: =IFERROR((N11 - J11)/J11, (N11 - K11)/K11) -> -0.0059715196
A12: Carangids nei | B12: 844429.78 | C12: =_xlfn.NUMBERVALUE(_xlfn.XLOOKUP(A12,Table8[Species name],Table8[min_price_kg],,0),".") -> 1 | D12: =_xlfn.NUMBERVALUE(_xlfn.XLOOKUP(A12,Table8[Species name],Table8[max_price_kg],,0),".") -> 1.8 | E12: =_xlfn.NUMBERVALUE(AVERAGE(C12:D12),".") -> 14 | F12: =(B12*C12)/1000000 -> 0.84442978 | G12: =(B12*D12)/1000000 -> 1.5199736 | I12: Kawakawa | J12: =SUMIFS(Data!F:F,Data!B:B,Analysis!$I15) -> 0 | K12: =SUMIFS(Data!H:H,Data!B:B,Analysis!$I15) -> 262828.54 | L12: =SUMIFS(Data!J:J,Data!B:B,Analysis!$I15) -> 271138.8 | M12: =SUMIFS(Data!L:L,Data!B:B,Analysis!$I15) -> 285110.92 | N12: =SUMIFS(Data!N:N,Data!B:B,Analysis!$I15) -> 280803.92 | O12: =IFERROR((N12 - J12)/J12, (N12 - K12)/K12) -> 0.06839204
A13: Groupers, seabasses nei | B13: 780975.85 | C13: =_xlfn.NUMBERVALUE(_xlfn.XLOOKUP(A13,Table8[Species name],Table8[min_price_kg],,0),".") -> 6 | D13: =_xlfn.NUMBERVALUE(_xlfn.XLOOKUP(A13,Table8[Species name],Table8[max_price_kg],,0),".") -> 11.5 | E13: =_xlfn.NUMBERVALUE(AVERAGE(C13:D13),".") -> 875 | F13: =(B13*C13)/1000000 -> 4.6858551 | G13: =(B13*D13)/1000000 -> 8.9812223 | I13: Marine fishes nei | J13: =SUMIFS(Data!F:F,Data!B:B,Analysis!$I3) -> 91386.2 | K13: =SUMIFS(Data!H:H,Data!B:B,Analysis!$I3) -> 183639.4 | L13: =SUMIFS(Data!J:J,Data!B:B,Analysis!$I3) -> 211135.31 | M13: =SUMIFS(Data!L:L,Data!B:B,Analysis!$I3) -> 175068.35 | N13: =SUMIFS(Data!N:N,Data!B:B,Analysis!$I3) -> 210719.99 | O13: =IFERROR((N13 - J13)/J13, (N13 - K13)/K13) -> 1.3058185
A14: Goldstripe sardinella | B14: 768268.37 | C14: =_xlfn.NUMBERVALUE(_xlfn.XLOOKUP(A14,Table8[Species name],Table8[min_price_kg],,0),".") -> 0.45 | D14: =_xlfn.NUMBERVALUE(_xlfn.XLOOKUP(A14,Table8[Species name],Table8[max_price_kg],,0),".") -> 0.85 | E14: =_xlfn.NUMBERVALUE(AVERAGE(C14:D14),".") -> 65 | F14: =(B14*C14)/1000000 -> 0.34572077 | G14: =(B14*D14)/1000000 -> 0.65302811 | I14: Carangids nei | J14: =SUMIFS(Data!F:F,Data!B:B,Analysis!$I12) -> 147505.09 | K14: =SUMIFS(Data!H:H,Data!B:B,Analysis!$I12) -> 129952.32 | L14: =SUMIFS(Data!J:J,Data!B:B,Analysis!$I12) -> 148146.42 | M14: =SUMIFS(Data!L:L,Data!B:B,Analysis!$I12) -> 146602.58 | N14: =SUMIFS(Data!N:N,Data!B:B,Analysis!$I12) -> 156308.93 | O14: =IFERROR((N14 - J14)/J14, (N14 - K14)/K14) -> 0.059684991
A15: Kawakawa | B15: 728515.34 | C15: =_xlfn.NUMBERVALUE(_xlfn.XLOOKUP(A15,Table8[Species name],Table8[min_price_kg],,0),".") -> 1.2 | D15: =_xlfn.NUMBERVALUE(_xlfn.XLOOKUP(A15,Table8[Species name],Table8[max_price_kg],,0),".") -> 1.75 | E15: =_xlfn.NUMBERVALUE(AVERAGE(C15:D15),".") -> 1475 | F15: =(B15*C15)/1000000 -> 0.87421841 | G15: =(B15*D15)/1000000 -> 1.2749018 | I15: Indian mackerels nei | J15: =SUMIFS(Data!F:F,Data!B:B,Analysis!$I6) -> 0 | K15: =SUMIFS(Data!H:H,Data!B:B,Analysis!$I6) -> 198720.41 | L15: =SUMIFS(Data!J:J,Data!B:B,Analysis!$I6) -> 140667.08 | M15: =SUMIFS(Data!L:L,Data!B:B,Analysis!$I6) -> 126823.43 | N15: =SUMIFS(Data!N:N,Data!B:B,Analysis!$I6) -> 123225.68 | O15: =IFERROR((N15 - J15)/J15, (N15 - K15)/K15) -> -0.37990426
A16: Yellowstripe scad | B16: 613546.24 | C16: =_xlfn.NUMBERVALUE(_xlfn.XLOOKUP(A16,Table8[Species name],Table8[min_price_kg],,0),".") -> 0.8 | D16: =_xlfn.NUMBERVALUE(_xlfn.XLOOKUP(A16,Table8[Species name],Table8[max_price_kg],,0),".") -> 1.35 | E16: =_xlfn.NUMBERVALUE(AVERAGE(C16:D16),".") -> 1075 | F16: =(B16*C16)/1000000 -> 0.49083699 | G16: =(B16*D16)/1000000 -> 0.82828742 | I16: Scads nei | J16: =SUMIFS(Data!F:F,Data!$B:B,Analysis!$I2) -> 238096.46 | K16: =SUMIFS(Data!H:H,Data!$B:B,Analysis!$I2) -> 254731.22 | L16: =SUMIFS(Data!J:J,Data!B:B,Analysis!$I2) -> 264606.66 | M16: =SUMIFS(Data!L:L,Data!B:B,Analysis!$I2) -> 291165.77 | N16: =SUMIFS(Data!N:N,Data!B:B,Analysis!$I2) -> 269843.16 | O16: =IFERROR((N16 - J16)/J16, (N16 - K16)/K16) -> 0.13333546
A17: Goatfishes | B17: 603736.31 | C17: =_xlfn.NUMBERVALUE(_xlfn.XLOOKUP(A17,Table8[Species name],Table8[min_price_kg],,0),".") -> 1.5 | D17: =_xlfn.NUMBERVALUE(_xlfn.XLOOKUP(A17,Table8[Species name],Table8[max_price_kg],,0),".") -> 3.2 | E17: =_xlfn.NUMBERVALUE(AVERAGE(C17:D17),".") -> 235 | F17: =(B17*C17)/1000000 -> 0.90560446 | G17: =(B17*D17)/1000000 -> 1.9319562 | I17: Narrow-barred Spanish mackerel | J17: =SUMIFS(Data!F:F,Data!B:B,Analysis!$I8) -> 107063.59 | K17: =SUMIFS(Data!H:H,Data!B:B,Analysis!$I8) -> 111395.37 | L17: =SUMIFS(Data!J:J,Data!B:B,Analysis!$I8) -> 114060.45 | M17: =SUMIFS(Data!L:L,Data!B:B,Analysis!$I8) -> 118856.09 | N17: =SUMIFS(Data!N:N,Data!B:B,Analysis!$I8) -> 152360.81 | O17: =IFERROR((N17 - J17)/J17, (N17 - K17)/K17) -> 0.42308706
A18: Anchovies, etc. nei | B18: 589436.6 | C18: =_xlfn.NUMBERVALUE(_xlfn.XLOOKUP(A18,Table8[Species name],Table8[min_price_kg],,0),".") -> 0.35 | D18: =_xlfn.NUMBERVALUE(_xlfn.XLOOKUP(A18,Table8[Species name],Table8[max_price_kg],,0),".") -> 0.95 | E18: =_xlfn.NUMBERVALUE(AVERAGE(C18:D18),".") -> 65 | F18: =(B18*C18)/1000000 -> 0.20630281 | G18: =(B18*D18)/1000000 -> 0.55996477 | I18: Common squids nei | J18: =SUMIFS(Data!F:F,Data!B:B,Analysis!$I7) -> 184648.68 | K18: =SUMIFS(Data!H:H,Data!B:B,Analysis!$I7) -> 132643.39 | L18: =SUMIFS(Data!J:J,Data!B:B,Analysis!$I7) -> 155358.81 | M18: =SUMIFS(Data!L:L,Data!B:B,Analysis!$I7) -> 208183.94 | N18: =SUMIFS(Data!N:N,Data!B:B,Analysis!$I7) -> 201599.74 | O18: =IFERROR((N18 - J18)/J18, (N18 - K18)/K18) -> 0.091801685
A19: Blue swimming crab | B19: 576846.93 | C19: =_xlfn.NUMBERVALUE(_xlfn.XLOOKUP(A19,Table8[Species name],Table8[min_price_kg],,0),".") -> 6.5 | D19: =_xlfn.NUMBERVALUE(_xlfn.XLOOKUP(A19,Table8[Species name],Table8[max_price_kg],,0),".") -> 12.5 | E19: =_xlfn.NUMBERVALUE(AVERAGE(C19:D19),".") -> 95 | F19: =(B19*C19)/1000000 -> 3.749505 | G19: =(B19*D19)/1000000 -> 7.2105866 | I19: Yellowstripe scad | J19: =SUMIFS(Data!F:F,Data!B:B,Analysis!$I16) -> 509734.73 | K19: =SUMIFS(Data!H:H,Data!B:B,Analysis!$I16) -> 518516.14 | L19: =SUMIFS(Data!J:J,Data!B:B,Analysis!$I16) -> 548659.91 | M19: =SUMIFS(Data!L:L,Data!B:B,Analysis!$I16) -> 527173.16 | N19: =SUMIFS(Data!N:N,Data!B:B,Analysis!$I16) -> 492396.62 | O19: =IFERROR((N19 - J19)/J19, (N19 - K19)/K19) -> -0.034013986
A20: Snappers, jobfishes nei | B20: 568351.95 | C20: =_xlfn.NUMBERVALUE(_xlfn.XLOOKUP(A20,Table8[Species name],Table8[min_price_kg],,0),".") -> 5.8 | D20: =_xlfn.NUMBERVALUE(_xlfn.XLOOKUP(A20,Table8[Species name],Table8[max_price_kg],,0),".") -> 9.5 | E20: =_xlfn.NUMBERVALUE(AVERAGE(C20:D20),".") -> 765 | F20: =(B20*C20)/1000000 -> 3.2964413 | G20: =(B20*D20)/1000000 -> 5.3993435 | I20: Goldstripe sardinella | J20: =SUMIFS(Data!F:F,Data!B:B,Analysis!$I14) -> 0 | K20: =SUMIFS(Data!H:H,Data!B:B,Analysis!$I14) -> 231539.22 | L20: =SUMIFS(Data!J:J,Data!B:B,Analysis!$I14) -> 221448.24 | M20: =SUMIFS(Data!L:L,Data!B:B,Analysis!$I14) -> 198263.94 | N20: =SUMIFS(Data!N:N,Data!B:B,Analysis!$I14) -> 193178.38 | O20: =IFERROR((N20 - J20)/J20, (N20 - K20)/K20) -> -0.1656775
A21: Sea catfishes nei | B21: 516015.28 | C21: =_xlfn.NUMBERVALUE(_xlfn.XLOOKUP(A21,Table8[Species name],Table8[min_price_kg],,0),".") -> 0.6 | D21: =_xlfn.NUMBERVALUE(_xlfn.XLOOKUP(A21,Table8[Species name],Table8[max_price_kg],,0),".") -> 1.25 | E21: =_xlfn.NUMBERVALUE(AVERAGE(C21:D21),".") -> 925 | F21: =(B21*C21)/1000000 -> 0.30960917 | G21: =(B21*D21)/1000000 -> 0.6450191 | I21: Groupers, seabasses nei | J21: =SUMIFS(Data!F:F,Data!B:B,Analysis!$I13) -> 1110233.2 | K21: =SUMIFS(Data!H:H,Data!B:B,Analysis!$I13) -> 300986.8 | L21: =SUMIFS(Data!J:J,Data!B:B,Analysis!$I13) -> 168759.68 | M21: =SUMIFS(Data!L:L,Data!B:B,Analysis!$I13) -> 182906.59 | N21: =SUMIFS(Data!N:N,Data!B:B,Analysis!$I13) -> 230761.9 | O21: =IFERROR((N21 - J21)/J21, (N21 - K21)/K21) -> -0.79215006
A22: Metapenaeus shrimps nei | B22: 466152.9
A23: Blood cockle | B23: 436929.58
A24: Ponyfishes(=Slipmouths) nei | B24: 436059.18
A25: Mullets nei | B25: 435672.44
A26: Spinefeet(=Rabbitfishes) nei | B26: 430449.99
A27: Stolephorus anchovies nei | B27: 425493.11
A28: Indian mackerel | B28: 386673.99
A29: Black pomfret | B29: 356835.93
A30: Nile tilapia | B30: 351905.41
A31: Threadfin breams nei | B31: 333037.98
A32: Short mackerel | B32: 331330.99
A33: Hairtails, scabbardfishes nei | B33: 317587.83
... A241: Cyclocheilichthys armatus | B241: 4.89

Sheet Dashboard
A1: Indonesia Fisheries Summary 2018-2022
C5: 2.596.481 Tonnes | J5: USD$ 5 MILLION | Q5: -0.79
C9: #1 SCADS | J9: #1 SNAPPERS | Q9: #1 GROUPERS
B33: CONCLUSION
B36: Scads have the highest catch volume (2.6M tonnes), making them the backbone of Indonesia's bulk fishery output. | I36: Snappers generate the best economic value ($5.03M), but Groupers in the second place declining fastest (-79%) threatening future revenue. | P36: High volume ≠ high revenue. Species with moderate catch but premium prices (Snappers, Blue Swimming Crab) often drives revenue more than bulk catch
B53: *Findings are based on 2018–2022 FAO data and local market prices. *Further analysis needed to establish causal links between fishing effort, environmental factors, and stock decline.

Sheet Top 5 Species by Catch
A1: Row Labels | B1: Sum of Total_Catch_tonnes
A2: Scads nei | B2: 2596480.6
A3: Marine fishes nei | B3: 1993648.2
A4: Skipjack tuna | B4: 1982631.8
A5: Yellowfin tuna | B5: 1318443.3 | H5: 2.596.481 Tonnes
A6: Indian mackerels nei | B6: 1099882.2
A7: Grand Total | B7: 8991086
H8: from 2018-2022
H9: #1 SCADS

Sheet Top 5 by Revenue
A1: Row Labels | B1: Sum of revenue_min_million
A2: Snappers nei | B2: 5.0291029
A3: Groupers, seabasses nei | B3: 4.6858551
A4: Blue swimming crab | B4: 3.749505 | F4: USD$ 5 MILLION
A5: Narrow-barred Spanish mackerel | B5: 3.3451382
A6: Snappers, jobfishes nei | B6: 3.2964413
A7: Grand Total | B7: 20.106043 | F7: from 2018-2022
F8: #1 SNAPPERS

Sheet Declining Species
A1: Row Labels | B1: Sum of % Change 2018-2022
A2: Groupers, seabasses nei | B2: -0.79215006
A3: Frigate tuna | B3: -0.4829709
A4: Yellowfin tuna | B4: -0.41408325
A5: Indian mackerels nei | B5: -0.37990426 | G5: -0.79
A6: Goldstripe sardinella | B6: -0.1656775
A7: Grand Total | B7: -2.234786
G8: from 2018-2022
G9: #1 GROUPERS
G11: SEABASSES
